<?xml version="1.0" ?>
<robot name="scara">

<material name="silver">
  <color rgba="0.700 0.700 0.700 1.000"/>
</material>

<link name="base_link">
  <inertial>
    <origin xyz="4.1348317138914987e-14 1.1442733399450669e-17 0.02538537549407115" rpy="0 0 0"/>
    <mass value="0.4212561589198547"/>
    <inertia ixx="0.0003523162719141013" iyy="0.000352316271806598" izz="0.0005205760399205217" ixy="5.784386303277816e-19" iyz="1.2236568192618244e-19" ixz="6.8933223187544176e-18"/>
  </inertial>
  <visual>
    <origin xyz="0 0 0" rpy="0 0 0"/>
    <geometry>
      <mesh filename="meshes/base_link.stl" scale="0.001 0.001 0.001"/>
    </geometry>
    <material name="silver"/>
    <material/>
  </visual>
  <collision>
    <origin xyz="0 0 0" rpy="0 0 0"/>
    <geometry>
      <mesh filename="meshes/base_link.stl" scale="0.001 0.001 0.001"/>
    </geometry>
  </collision>
</link>

<link name="link11">
  <inertial>
    <origin xyz="0.10525196449079027 -6.33520744229443e-18 0.007893897336813394" rpy="0 0 0"/>
    <mass value="0.19021957699504854"/>
    <inertia ixx="4.266406720619166e-05" iyy="0.0009127379856432773" izz="0.0009460800362480377" ixy="-2.352943310600468e-19" iyz="2.0614230405701387e-20" ixz="-7.099184615224144e-06"/>
  </inertial>
  <visual>
    <origin xyz="-0.0 -0.0 -0.05" rpy="0 0 0"/>
    <geometry>
      <mesh filename="meshes/link11.stl" scale="0.001 0.001 0.001"/>
    </geometry>
    <material name="silver"/>
    <material/>
  </visual>
  <collision>
    <origin xyz="-0.0 -0.0 -0.05" rpy="0 0 0"/>
    <geometry>
      <mesh filename="meshes/link11.stl" scale="0.001 0.001 0.001"/>
    </geometry>
  </collision>
</link>

<link name="link21">
  <inertial>
    <origin xyz="0.07997954379107086 4.004399108162525e-18 0.007997954379114033" rpy="0 0 0"/>
    <mass value="0.1504695769950486"/>
    <inertia ixx="3.3629708025766135e-05" iyy="0.0004539463066041121" izz="0.0004797602163893015" ixy="1.2038479109455222e-20" iyz="-4.2190142483713765e-21" ixz="-5.246421657145381e-06"/>
  </inertial>
  <visual>
    <origin xyz="-0.2 -0.0 -0.065" rpy="0 0 0"/>
    <geometry>
      <mesh filename="meshes/link21.stl" scale="0.001 0.001 0.001"/>
    </geometry>
    <material name="silver"/>
    <material/>
  </visual>
  <collision>
    <origin xyz="-0.2 -0.0 -0.065" rpy="0 0 0"/>
    <geometry>
      <mesh filename="meshes/link21.stl" scale="0.001 0.001 0.001"/>
    </geometry>
  </collision>
</link>

<link name="link31">
  <inertial>
    <origin xyz="0.052362335566963236 2.849578646508859e-18 0.007499999999999993" rpy="0 0 0"/>
    <mass value="0.10572444467584055"/>
    <inertia ixx="2.329801395883728e-05" iyy="0.0001710816166802763" izz="0.00019041496396376284" ixy="4.740856971380394e-20" iyz="-2.259525899717117e-21" ixz="0.0"/>
  </inertial>
  <visual>
    <origin xyz="-0.35 -0.0 -0.08" rpy="0 0 0"/>
    <geometry>
      <mesh filename="meshes/link31.stl" scale="0.001 0.001 0.001"/>
    </geometry>
    <material name="silver"/>
    <material/>
  </visual>
  <collision>
    <origin xyz="-0.35 -0.0 -0.08" rpy="0 0 0"/>
    <geometry>
      <mesh filename="meshes/link31.stl" scale="0.001 0.001 0.001"/>
    </geometry>
  </collision>
</link>

<joint name="Revolute_1" type="continuous">
  <origin xyz="0.0 0.0 0.05" rpy="0 0 0"/>
  <parent link="base_link"/>
  <child link="link11"/>
  <axis xyz="0.0 0.0 1.0"/>
</joint>
<transmission name="Revolute_1_tran">
  <type>transmission_interface/SimpleTransmission</type>
  <joint name="Revolute_1">
    <hardwareInterface>PositionJointInterface</hardwareInterface>
  </joint>
  <actuator name="Revolute_1_actr">
    <hardwareInterface>PositionJointInterface</hardwareInterface>
    <mechanicalReduction>1</mechanicalReduction>
  </actuator>
</transmission>

<joint name="Revolute_2" type="continuous">
  <origin xyz="0.2 0.0 0.015" rpy="0 0 0"/>
  <parent link="link11"/>
  <child link="link21"/>
  <axis xyz="0.0 0.0 1.0"/>
</joint>
<transmission name="Revolute_2_tran">
  <type>transmission_interface/SimpleTransmission</type>
  <joint name="Revolute_2">
    <hardwareInterface>PositionJointInterface</hardwareInterface>
  </joint>
  <actuator name="Revolute_2_actr">
    <hardwareInterface>PositionJointInterface</hardwareInterface>
    <mechanicalReduction>1</mechanicalReduction>
  </actuator>
</transmission>

<joint name="Revolute_3" type="continuous">
  <origin xyz="0.15 0.0 0.015" rpy="0 0 0"/>
  <parent link="link21"/>
  <child link="link31"/>
  <axis xyz="0.0 0.0 1.0"/>
</joint>
<transmission name="Revolute_3_tran">
  <type>transmission_interface/SimpleTransmission</type>
  <joint name="Revolute_3">
    <hardwareInterface>PositionJointInterface</hardwareInterface>
  </joint>
  <actuator name="Revolute_3_actr">
    <hardwareInterface>PositionJointInterface</hardwareInterface>
    <mechanicalReduction>1</mechanicalReduction>
  </actuator>
</transmission>

</robot>
