<?xml version="1.0"?>
<robot name="robot_revolute">

  <link name="base_link">
    <inertial>
      <mass value="1.0"/>
      <origin xyz="0 0 0" rpy="0 0 0"/>
      <inertia 
        ixx="0.1" ixy="0.0" ixz="0.0"
        iyy="0.1" iyz="0.0"
        izz="0.1"/>
    </inertial>
    <visual>
      <origin xyz="0 0 0" rpy="0 0 0"/>
      <geometry><box size="0.2 0.2 0.2"/></geometry>
      <material name="Gray"><color rgba="0.6 0.6 0.6 1.0"/></material>
    </visual>
    <collision>
      <origin xyz="0 0 0" rpy="0 0 0"/>
      <geometry><box size="0.2 0.2 0.2"/></geometry>
    </collision>
  </link>

  <link name="link1">
    <inertial>
      <mass value="0.5"/>
      <origin xyz="0.1 0 0" rpy="0 0 0"/>
      <inertia 
        ixx="0.05" ixy="0.0" ixz="0.0"
        iyy="0.05" iyz="0.0"
        izz="0.05"/>
    </inertial>
    <visual>
      <origin xyz="0.1 0 0" rpy="0 0 0"/>
      <geometry><cylinder length="0.2" radius="0.05"/></geometry>
      <material name="Blue"><color rgba="0.2 0.2 0.8 1.0"/></material>
    </visual>
    <collision>
      <origin xyz="0.1 0 0" rpy="0 0 0"/>
      <geometry><cylinder length="0.2" radius="0.05"/></geometry>
    </collision>
  </link>

  <joint name="joint_revolute_1" type="revolute">
    <parent link="base_link"/>
    <child link="link1"/>
    <axis xyz="0 0 1"/>
    <origin xyz="0 0 0" rpy="0 0 0"/>
    <limit lower="-1.57" upper="1.57" effort="10" velocity="1.0"/>
  </joint>

</robot>
