<?xml version="1.0" encoding="utf-8"?>
<robot xmlns:xacro="http://www.ros.org/wiki/xacro" name="robot_scara">

  <!-- === Base Link === -->
  <link name="base_link">
    <visual>
      <origin xyz="0 0 0.1" rpy="0 0 0"/>
      <geometry><box size="0.1 0.15 0.2"/></geometry>
      <material name="grey"><color rgba="0.1 0.1 0.1 1.0"/></material>
    </visual>
    <collision>
      <origin xyz="0 0 0.1" rpy="0 0 0"/>
      <geometry><box size="0.1 0.15 0.2"/></geometry>
    </collision>
    <inertial>
      <origin xyz="0 0 0" rpy="0 0 0"/>
      <mass value="1"/>
      <inertia ixx="1.0" ixy="0.0" ixz="0.0" iyy="1.0" iyz="0.0" izz="1.0"/>
    </inertial>
  </link>

  <!-- === Link 1 === -->
  <link name="link_1">
    <visual>
      <origin xyz="0.25 0 0" rpy="0 0 0"/>
      <geometry><box size="0.5 0.05 0.05"/></geometry>
      <material name="red"><color rgba="1.0 0.0 0.0 1.0"/></material>
    </visual>
    <collision>
      <origin xyz="0.25 0 0" rpy="0 0 0"/>
      <geometry><box size="0.5 0.05 0.05"/></geometry>
    </collision>
    <inertial>
      <origin xyz="0 0 0" rpy="0 0 0"/>
      <mass value="1"/>
      <inertia ixx="1.0" ixy="0.0" ixz="0.0" iyy="1.0" iyz="0.0" izz="1.0"/>
    </inertial>
  </link>
  <joint name="link_1_joint" type="revolute">
    <parent link="base_link"/>
    <child  link="link_1"/>
    <origin xyz="0 0 0.225" rpy="0 0 0"/>
    <axis  xyz="0 0 1"/>
    <limit lower="-3.14159" upper="3.14159" effort="1000.0" velocity="50.0"/>
  </joint>

  <!-- === Link 2 === -->
  <link name="link_2">
    <visual>
      <origin xyz="0.25 0 0" rpy="0 0 0"/>
      <geometry><box size="0.5 0.05 0.05"/></geometry>
      <material name="green"><color rgba="0.0 1.0 0.0 1.0"/></material>
    </visual>
    <collision>
      <origin xyz="0.25 0 0" rpy="0 0 0"/>
      <geometry><box size="0.5 0.05 0.05"/></geometry>
    </collision>
    <inertial>
      <origin xyz="0 0 0" rpy="0 0 0"/>
      <mass value="1"/>
      <inertia ixx="1.0" ixy="0.0" ixz="0.0" iyy="1.0" iyz="0.0" izz="1.0"/>
    </inertial>
  </link>
  <joint name="link_2_joint" type="revolute">
    <parent link="link_1"/>
    <child  link="link_2"/>
    <origin xyz="0.45 0 0.05" rpy="0 0 0"/>
    <axis  xyz="0 0 1"/>
    <limit lower="-3.14159" upper="3.14159" effort="1000.0" velocity="50.0"/>
  </joint>

  <!-- === Link 3 === -->
  <link name="link_3">
    <visual>
      <origin xyz="0.15 0 0" rpy="0 0 0"/>
      <geometry><box size="0.3 0.05 0.05"/></geometry>
      <material name="blue"><color rgba="0.0 0.0 1.0 1.0"/></material>
    </visual>
    <collision>
      <origin xyz="0.15 0 0" rpy="0 0 0"/>
      <geometry><box size="0.3 0.05 0.05"/></geometry>
    </collision>
    <inertial>
      <origin xyz="0 0 0" rpy="0 0 0"/>
      <mass value="1"/>
      <inertia ixx="1.0" ixy="0.0" ixz="0.0" iyy="1.0" iyz="0.0" izz="1.0"/>
    </inertial>
  </link>
  <joint name="link_3_joint" type="revolute">
    <parent link="link_2"/>
    <child  link="link_3"/>
    <origin xyz="0.45 0 -0.05" rpy="0 0 0"/>
    <axis  xyz="0 0 1"/>
    <limit lower="-3.14159" upper="3.14159" effort="1000.0" velocity="50.0"/>
  </joint>

  <link name="world" />

  <joint name="world_to_base_link=" type="fixed">
    <parent link="world"/>
    <child link="base_link"/>
  </joint>


  <!-- === ros2_control Configuration === -->
  <ros2_control name="scara_hw" type="system">
    <hardware>
      <plugin>gazebo_ros2_control/GazeboSystem</plugin>
    </hardware>
    <joint name="link_1_joint">
      <command_interface name="position"/>
      <state_interface name="position"/>
      <state_interface name="velocity"/>
      <state_interface name="effort"/>
    </joint>
    <joint name="link_2_joint">
      <command_interface name="position"/>
      <state_interface name="position"/>
      <state_interface name="velocity"/>
      <state_interface name="effort"/>
    </joint>
    <joint name="link_3_joint">
      <command_interface name="position"/>
      <state_interface name="position"/>
      <state_interface name="velocity"/>
      <state_interface name="effort"/>
    </joint>
  </ros2_control>

  <!-- === Gazebo ROS2 Control plugin === -->
  <gazebo>
    <plugin name="gazebo_ros2_control" filename="libgazebo_ros2_control.so">
      <parameters>$(find scara_control)/config/scara_controllers.yaml</parameters>
      <robot_param_node>robot_state_publisher</robot_param_node>
      <robot_sim_type>gazebo_ros2_control/GazeboSim</robot_sim_type>
    </plugin>
  </gazebo>

</robot>
